<?xml version='1.0' encoding='utf-8'?>
<mujoco model="quadcopter_drone">
  <compiler angle="radian" meshdir="D:\ROS2_PROJECT\robotstudio\examples\quadcopter_drone\meshes" autolimits="true" />
  <option timestep="0.001" gravity="0 0 -9.81" />
  <default>
    <geom rgba="0.8 0.6 0.4 1" friction="1 0.5 0.5" />
  </default>
  <asset>
    <material name="body_color" rgba="0.1 0.1 0.1 1.0" />
    <material name="sensor_color" rgba="0.8 0.2 0.2 1.0" />
    <material name="gps_color" rgba="0.2 0.8 0.2 1.0" />
    <material name="motor_color" rgba="0.3 0.3 0.3 1.0" />
    <material name="prop_color" rgba="0.9 0.9 0.9 0.8" />
    <material name="camera_color" rgba="0.2 0.2 0.8 1.0" />
  </asset>
  <worldbody>
    <light diffuse="0.5 0.5 0.5" pos="0 0 3" dir="0 0 -1" />
    <geom name="floor" type="plane" size="0 0 1" rgba="0.9 0.9 0.9 1" />
    <body name="base_link" pos="0 0 0.5">
      <freejoint name="base_link_freejoint" />
      <inertial mass="1.0" pos="0 0 0" fullinertia="0.0104 0.0104 0.0208 0.0 0.0 0.0" />
      <geom name="base_link_visual" type="box" group="0" pos="0 0 0" size="0.125 0.125 0.05" material="body_color" />
      <geom name="base_link_collision" type="box" group="3" rgba="0.5 0.5 0.5 0.3" pos="0 0 0" size="0.125 0.125 0.05" />
      <body name="imu_link" pos="0 0 0">
        <inertial mass="0.01" pos="0 0 0" fullinertia="0.00001 0.00001 0.00001 0.0 0.0 0.0" />
        <geom name="imu_link_visual" type="box" group="0" pos="0 0 0" size="0.01 0.01 0.005" material="sensor_color" />
        <geom name="imu_link_collision" type="box" group="3" rgba="0.5 0.5 0.5 0.3" pos="0 0 0" size="0.01 0.01 0.005" />
      </body>
      <body name="gps_link" pos="0 0 0.06">
        <inertial mass="0.01" pos="0 0 0" fullinertia="0.00001 0.00001 0.00001 0.0 0.0 0.0" />
        <geom name="gps_link_visual" type="cylinder" group="0" pos="0 0 0" size="0.015 0.01" material="gps_color" />
        <geom name="gps_link_collision" type="cylinder" group="3" rgba="0.5 0.5 0.5 0.3" pos="0 0 0" size="0.015 0.01" />
      </body>
      <body name="rotor_1_link" pos="0.177 0.177 0.05" quat="0.9239556994702721 0.0 0.0 0.3824994972760097">
        <joint name="rotor_1_joint" type="hinge" axis="0 0 1" damping="0.01" frictionloss="0.001" />
        <inertial mass="0.12" pos="0 0 0.015" fullinertia="0.0001 0.0001 0.0002 0.0 0.0 0.0" />
        <geom name="rotor_1_link_visual" type="cylinder" group="0" pos="0 0 0" size="0.015 0.015" material="motor_color" />
        <geom name="rotor_1_link_visual_1" type="cylinder" group="0" pos="0 0 0.02" size="0.127 0.0025" material="prop_color" />
        <geom name="rotor_1_link_collision" type="cylinder" group="3" rgba="0.5 0.5 0.5 0.3" pos="0 0 0" size="0.015 0.015" />
      </body>
      <body name="rotor_2_link" pos="0.177 -0.177 0.05" quat="0.9239556994702721 0.0 0.0 -0.3824994972760097">
        <joint name="rotor_2_joint" type="hinge" axis="0 0 1" damping="0.01" frictionloss="0.001" />
        <inertial mass="0.12" pos="0 0 0.015" fullinertia="0.0001 0.0001 0.0002 0.0 0.0 0.0" />
        <geom name="rotor_2_link_visual" type="cylinder" group="0" pos="0 0 0" size="0.015 0.015" material="motor_color" />
        <geom name="rotor_2_link_visual_1" type="cylinder" group="0" pos="0 0 0.02" size="0.127 0.0025" material="prop_color" />
        <geom name="rotor_2_link_collision" type="cylinder" group="3" rgba="0.5 0.5 0.5 0.3" pos="0 0 0" size="0.015 0.015" />
      </body>
      <body name="rotor_3_link" pos="-0.177 -0.177 0.05" quat="0.38277327330949534 0.0 0.0 -0.9238423140557778">
        <joint name="rotor_3_joint" type="hinge" axis="0 0 1" damping="0.01" frictionloss="0.001" />
        <inertial mass="0.12" pos="0 0 0.015" fullinertia="0.0001 0.0001 0.0002 0.0 0.0 0.0" />
        <geom name="rotor_3_link_visual" type="cylinder" group="0" pos="0 0 0" size="0.015 0.015" material="motor_color" />
        <geom name="rotor_3_link_visual_1" type="cylinder" group="0" pos="0 0 0.02" size="0.127 0.0025" material="prop_color" />
        <geom name="rotor_3_link_collision" type="cylinder" group="3" rgba="0.5 0.5 0.5 0.3" pos="0 0 0" size="0.015 0.015" />
      </body>
      <body name="rotor_4_link" pos="-0.177 0.177 0.05" quat="0.38277327330949534 0.0 0.0 0.9238423140557778">
        <joint name="rotor_4_joint" type="hinge" axis="0 0 1" damping="0.01" frictionloss="0.001" />
        <inertial mass="0.12" pos="0 0 0.015" fullinertia="0.0001 0.0001 0.0002 0.0 0.0 0.0" />
        <geom name="rotor_4_link_visual" type="cylinder" group="0" pos="0 0 0" size="0.015 0.015" material="motor_color" />
        <geom name="rotor_4_link_visual_1" type="cylinder" group="0" pos="0 0 0.02" size="0.127 0.0025" material="prop_color" />
        <geom name="rotor_4_link_collision" type="cylinder" group="3" rgba="0.5 0.5 0.5 0.3" pos="0 0 0" size="0.015 0.015" />
      </body>
      <body name="camera_link" pos="0.13 0 0">
        <inertial mass="0.01" pos="0 0 0" fullinertia="0.00001 0.00001 0.00001 0.0 0.0 0.0" />
        <geom name="camera_link_visual" type="box" group="0" pos="0 0 0" size="0.01 0.015 0.0075" material="camera_color" />
        <geom name="camera_link_collision" type="box" group="3" rgba="0.5 0.5 0.5 0.3" pos="0 0 0" size="0.01 0.015 0.0075" />
      </body>
    </body>
  </worldbody>
  <actuator>
    <position name="rotor_1_joint_motor" joint="rotor_1_joint" kp="10" ctrlrange="-10.0 10.0" />
    <position name="rotor_2_joint_motor" joint="rotor_2_joint" kp="10" ctrlrange="-10.0 10.0" />
    <position name="rotor_3_joint_motor" joint="rotor_3_joint" kp="10" ctrlrange="-10.0 10.0" />
    <position name="rotor_4_joint_motor" joint="rotor_4_joint" kp="10" ctrlrange="-10.0 10.0" />
  </actuator>
  <sensor>
    <jointpos name="rotor_1_joint_pos" joint="rotor_1_joint" />
    <jointvel name="rotor_1_joint_vel" joint="rotor_1_joint" />
    <jointpos name="rotor_2_joint_pos" joint="rotor_2_joint" />
    <jointvel name="rotor_2_joint_vel" joint="rotor_2_joint" />
    <jointpos name="rotor_3_joint_pos" joint="rotor_3_joint" />
    <jointvel name="rotor_3_joint_vel" joint="rotor_3_joint" />
    <jointpos name="rotor_4_joint_pos" joint="rotor_4_joint" />
    <jointvel name="rotor_4_joint_vel" joint="rotor_4_joint" />
  </sensor>
</mujoco>