<?xml version='1.0' encoding='utf-8'?>
<mujoco model="robotic_arm_6dof">
  <compiler angle="radian" meshdir="D:\ROS2_PROJECT\robotstudio\examples\robotic_arm_6dof\meshes" autolimits="true" />
  <option timestep="0.001" gravity="0 0 -9.81" />
  <default>
    <geom rgba="0.8 0.6 0.4 1" friction="1 0.5 0.5" />
  </default>
  <asset>
    <material name="grey" rgba="0.5 0.5 0.5 1.0" />
    <material name="blue" rgba="0.2 0.3 0.8 1.0" />
    <material name="orange" rgba="0.9 0.5 0.2 1.0" />
    <material name="green" rgba="0.2 0.8 0.3 1.0" />
    <material name="yellow" rgba="0.9 0.9 0.2 1.0" />
    <material name="purple" rgba="0.7 0.2 0.7 1.0" />
    <material name="cyan" rgba="0.2 0.8 0.8 1.0" />
    <material name="red" rgba="0.8 0.2 0.2 1.0" />
  </asset>
  <worldbody>
    <light diffuse="0.5 0.5 0.5" pos="0 0 3" dir="0 0 -1" />
    <geom name="floor" type="plane" size="0 0 1" rgba="0.9 0.9 0.9 1" />
    <body name="base_link" pos="0 0 0.5">
      <freejoint name="base_link_freejoint" />
      <inertial mass="2.0" pos="0 0 0" fullinertia="0.01 0.01 0.01 0 0 0" />
      <geom name="base_link_visual" type="cylinder" group="0" size="0.08 0.025" material="grey" />
      <geom name="base_link_collision" type="cylinder" group="3" rgba="0.5 0.5 0.5 0.3" size="0.08 0.025" />
      <body name="link1" pos="0 0 0.025">
        <joint name="joint1" type="hinge" axis="0 0 1" range="-3.14 3.14" />
        <inertial mass="1.0" pos="0 0 0" fullinertia="0.01 0.01 0.01 0 0 0" />
        <geom name="link1_visual" type="box" group="0" pos="0 0 0.075" size="0.03 0.03 0.075" material="blue" />
        <body name="link2" pos="0 0 0.15">
          <joint name="joint2" type="hinge" axis="0 1 0" range="-1.57 1.57" />
          <inertial mass="0.8" pos="0 0 0" fullinertia="0.008 0.008 0.008 0 0 0" />
          <geom name="link2_visual" type="box" group="0" pos="0 0 0.125" size="0.025 0.025 0.125" material="orange" />
          <body name="link3" pos="0 0 0.25">
            <joint name="joint3" type="hinge" axis="0 1 0" range="-1.57 1.57" />
            <inertial mass="0.6" pos="0 0 0" fullinertia="0.006 0.006 0.006 0 0 0" />
            <geom name="link3_visual" type="box" group="0" pos="0 0 0.125" size="0.0225 0.0225 0.125" material="green" />
            <body name="link4" pos="0 0 0.25">
              <joint name="joint4" type="hinge" axis="0 0 1" range="-3.14 3.14" />
              <inertial mass="0.3" pos="0 0 0" fullinertia="0.003 0.003 0.003 0 0 0" />
              <geom name="link4_visual" type="cylinder" group="0" pos="0 0 0.06" size="0.02 0.06" material="yellow" />
              <body name="link5" pos="0 0 0.12">
                <joint name="joint5" type="hinge" axis="0 1 0" range="-1.57 1.57" />
                <inertial mass="0.2" pos="0 0 0" fullinertia="0.002 0.002 0.002 0 0 0" />
                <geom name="link5_visual" type="box" group="0" pos="0 0 0.04" size="0.02 0.02 0.04" material="purple" />
                <body name="link6" pos="0 0 0.08">
                  <joint name="joint6" type="hinge" axis="0 0 1" range="-3.14 3.14" />
                  <inertial mass="0.1" pos="0 0 0" fullinertia="0.001 0.001 0.001 0 0 0" />
                  <geom name="link6_visual" type="cylinder" group="0" pos="0 0 0.02" size="0.015 0.02" material="cyan" />
                  <body name="ee_link" pos="0 0 0.04">
                    <inertial mass="0.05" pos="0 0 0" fullinertia="0.0005 0.0005 0.0005 0 0 0" />
                    <geom name="ee_link_visual" type="box" group="0" size="0.015 0.025 0.01" material="red" />
                  </body>
                </body>
              </body>
            </body>
          </body>
        </body>
      </body>
    </body>
  </worldbody>
  <actuator>
    <position name="joint1_motor" joint="joint1" kp="10" ctrlrange="-100 100" />
    <position name="joint2_motor" joint="joint2" kp="10" ctrlrange="-80 80" />
    <position name="joint3_motor" joint="joint3" kp="10" ctrlrange="-60 60" />
    <position name="joint4_motor" joint="joint4" kp="10" ctrlrange="-40 40" />
    <position name="joint5_motor" joint="joint5" kp="10" ctrlrange="-30 30" />
    <position name="joint6_motor" joint="joint6" kp="10" ctrlrange="-20 20" />
  </actuator>
  <sensor>
    <jointpos name="joint1_pos" joint="joint1" />
    <jointvel name="joint1_vel" joint="joint1" />
    <jointpos name="joint2_pos" joint="joint2" />
    <jointvel name="joint2_vel" joint="joint2" />
    <jointpos name="joint3_pos" joint="joint3" />
    <jointvel name="joint3_vel" joint="joint3" />
    <jointpos name="joint4_pos" joint="joint4" />
    <jointvel name="joint4_vel" joint="joint4" />
    <jointpos name="joint5_pos" joint="joint5" />
    <jointvel name="joint5_vel" joint="joint5" />
    <jointpos name="joint6_pos" joint="joint6" />
    <jointvel name="joint6_vel" joint="joint6" />
  </sensor>
</mujoco>