<?xml version='1.0' encoding='utf-8'?>
<mujoco model="quadruped_robot">
  <compiler angle="radian" meshdir="D:\ROS2_PROJECT\robotstudio\examples\quadruped_robot\meshes" autolimits="true" />
  <option timestep="0.001" gravity="0 0 -9.81" />
  <default>
    <geom rgba="0.8 0.6 0.4 1" friction="1 0.5 0.5" />
  </default>
  <asset>
    <material name="body_color" rgba="0.8 0.8 0.8 1.0" />
    <material name="hip_color" rgba="0.3 0.3 0.3 1.0" />
    <material name="leg_color" rgba="0.2 0.2 0.8 1.0" />
  </asset>
  <worldbody>
    <light diffuse="0.5 0.5 0.5" pos="0 0 3" dir="0 0 -1" />
    <geom name="floor" type="plane" size="0 0 1" rgba="0.9 0.9 0.9 1" />
    <body name="base_link" pos="0 0 0.5">
      <freejoint name="base_link_freejoint" />
      <inertial mass="15.0" pos="0 0 0" fullinertia="0.225 0.775 0.925 0.0 0.0 0.0" />
      <geom name="base_link_visual" type="box" group="0" pos="0 0 0" size="0.3 0.2 0.1" material="body_color" />
      <geom name="base_link_collision" type="box" group="3" rgba="0.5 0.5 0.5 0.3" pos="0 0 0" size="0.3 0.2 0.1" />
      <body name="front_left_hip" pos="0.25 0.15 -0.1">
        <joint name="front_left_hip_joint" type="hinge" axis="0 0 1" range="-0.785 0.785" damping="0.5" frictionloss="0.1" />
        <inertial mass="1.0" pos="0 0 -0.05" fullinertia="0.001 0.001 0.001 0.0 0.0 0.0" />
        <geom name="front_left_hip_visual" type="cylinder" group="0" pos="0 0 -0.05" size="0.04 0.05" material="hip_color" />
        <geom name="front_left_hip_collision" type="cylinder" group="3" rgba="0.5 0.5 0.5 0.3" pos="0 0 -0.05" size="0.04 0.05" />
        <body name="front_left_upper_leg" pos="0 0 -0.1">
          <joint name="front_left_shoulder_joint" type="hinge" axis="1 0 0" range="-1.047 1.047" damping="0.5" frictionloss="0.1" />
          <inertial mass="0.8" pos="0 0 -0.15" fullinertia="0.006 0.006 0.0007 0.0 0.0 0.0" />
          <geom name="front_left_upper_leg_visual" type="cylinder" group="0" pos="0 0 -0.15" size="0.03 0.15" material="leg_color" />
          <geom name="front_left_upper_leg_collision" type="cylinder" group="3" rgba="0.5 0.5 0.5 0.3" pos="0 0 -0.15" size="0.03 0.15" />
          <body name="front_left_lower_leg" pos="0 0 -0.3">
            <joint name="front_left_knee_joint" type="hinge" axis="1 0 0" range="-2.094 -0.174" damping="0.5" frictionloss="0.1" />
            <inertial mass="0.7" pos="0 0 -0.15" fullinertia="0.005 0.005 0.0006 0.0 0.0 0.0" />
            <geom name="front_left_lower_leg_visual" type="cylinder" group="0" pos="0 0 -0.15" size="0.025 0.15" material="leg_color" />
            <geom name="front_left_lower_leg_collision" type="cylinder" group="3" rgba="0.5 0.5 0.5 0.3" pos="0 0 -0.15" size="0.025 0.15" />
          </body>
        </body>
      </body>
      <body name="front_right_hip" pos="0.25 -0.15 -0.1">
        <joint name="front_right_hip_joint" type="hinge" axis="0 0 1" range="-0.785 0.785" damping="0.5" frictionloss="0.1" />
        <inertial mass="1.0" pos="0 0 -0.05" fullinertia="0.001 0.001 0.001 0.0 0.0 0.0" />
        <geom name="front_right_hip_visual" type="cylinder" group="0" pos="0 0 -0.05" size="0.04 0.05" material="hip_color" />
        <geom name="front_right_hip_collision" type="cylinder" group="3" rgba="0.5 0.5 0.5 0.3" pos="0 0 -0.05" size="0.04 0.05" />
        <body name="front_right_upper_leg" pos="0 0 -0.1">
          <joint name="front_right_shoulder_joint" type="hinge" axis="1 0 0" range="-1.047 1.047" damping="0.5" frictionloss="0.1" />
          <inertial mass="0.8" pos="0 0 -0.15" fullinertia="0.006 0.006 0.0007 0.0 0.0 0.0" />
          <geom name="front_right_upper_leg_visual" type="cylinder" group="0" pos="0 0 -0.15" size="0.03 0.15" material="leg_color" />
          <geom name="front_right_upper_leg_collision" type="cylinder" group="3" rgba="0.5 0.5 0.5 0.3" pos="0 0 -0.15" size="0.03 0.15" />
          <body name="front_right_lower_leg" pos="0 0 -0.3">
            <joint name="front_right_knee_joint" type="hinge" axis="1 0 0" range="-2.094 -0.174" damping="0.5" frictionloss="0.1" />
            <inertial mass="0.7" pos="0 0 -0.15" fullinertia="0.005 0.005 0.0006 0.0 0.0 0.0" />
            <geom name="front_right_lower_leg_visual" type="cylinder" group="0" pos="0 0 -0.15" size="0.025 0.15" material="leg_color" />
            <geom name="front_right_lower_leg_collision" type="cylinder" group="3" rgba="0.5 0.5 0.5 0.3" pos="0 0 -0.15" size="0.025 0.15" />
          </body>
        </body>
      </body>
      <body name="rear_left_hip" pos="-0.25 0.15 -0.1">
        <joint name="rear_left_hip_joint" type="hinge" axis="0 0 1" range="-0.785 0.785" damping="0.5" frictionloss="0.1" />
        <inertial mass="1.0" pos="0 0 -0.05" fullinertia="0.001 0.001 0.001 0.0 0.0 0.0" />
        <geom name="rear_left_hip_visual" type="cylinder" group="0" pos="0 0 -0.05" size="0.04 0.05" material="hip_color" />
        <geom name="rear_left_hip_collision" type="cylinder" group="3" rgba="0.5 0.5 0.5 0.3" pos="0 0 -0.05" size="0.04 0.05" />
        <body name="rear_left_upper_leg" pos="0 0 -0.1">
          <joint name="rear_left_shoulder_joint" type="hinge" axis="1 0 0" range="-1.047 1.047" damping="0.5" frictionloss="0.1" />
          <inertial mass="0.8" pos="0 0 -0.15" fullinertia="0.006 0.006 0.0007 0.0 0.0 0.0" />
          <geom name="rear_left_upper_leg_visual" type="cylinder" group="0" pos="0 0 -0.15" size="0.03 0.15" material="leg_color" />
          <geom name="rear_left_upper_leg_collision" type="cylinder" group="3" rgba="0.5 0.5 0.5 0.3" pos="0 0 -0.15" size="0.03 0.15" />
          <body name="rear_left_lower_leg" pos="0 0 -0.3">
            <joint name="rear_left_knee_joint" type="hinge" axis="1 0 0" range="-2.094 -0.174" damping="0.5" frictionloss="0.1" />
            <inertial mass="0.7" pos="0 0 -0.15" fullinertia="0.005 0.005 0.0006 0.0 0.0 0.0" />
            <geom name="rear_left_lower_leg_visual" type="cylinder" group="0" pos="0 0 -0.15" size="0.025 0.15" material="leg_color" />
            <geom name="rear_left_lower_leg_collision" type="cylinder" group="3" rgba="0.5 0.5 0.5 0.3" pos="0 0 -0.15" size="0.025 0.15" />
          </body>
        </body>
      </body>
      <body name="rear_right_hip" pos="-0.25 -0.15 -0.1">
        <joint name="rear_right_hip_joint" type="hinge" axis="0 0 1" range="-0.785 0.785" damping="0.5" frictionloss="0.1" />
        <inertial mass="1.0" pos="0 0 -0.05" fullinertia="0.001 0.001 0.001 0.0 0.0 0.0" />
        <geom name="rear_right_hip_visual" type="cylinder" group="0" pos="0 0 -0.05" size="0.04 0.05" material="hip_color" />
        <geom name="rear_right_hip_collision" type="cylinder" group="3" rgba="0.5 0.5 0.5 0.3" pos="0 0 -0.05" size="0.04 0.05" />
        <body name="rear_right_upper_leg" pos="0 0 -0.1">
          <joint name="rear_right_shoulder_joint" type="hinge" axis="1 0 0" range="-1.047 1.047" damping="0.5" frictionloss="0.1" />
          <inertial mass="0.8" pos="0 0 -0.15" fullinertia="0.006 0.006 0.0007 0.0 0.0 0.0" />
          <geom name="rear_right_upper_leg_visual" type="cylinder" group="0" pos="0 0 -0.15" size="0.03 0.15" material="leg_color" />
          <geom name="rear_right_upper_leg_collision" type="cylinder" group="3" rgba="0.5 0.5 0.5 0.3" pos="0 0 -0.15" size="0.03 0.15" />
          <body name="rear_right_lower_leg" pos="0 0 -0.3">
            <joint name="rear_right_knee_joint" type="hinge" axis="1 0 0" range="-2.094 -0.174" damping="0.5" frictionloss="0.1" />
            <inertial mass="0.7" pos="0 0 -0.15" fullinertia="0.005 0.005 0.0006 0.0 0.0 0.0" />
            <geom name="rear_right_lower_leg_visual" type="cylinder" group="0" pos="0 0 -0.15" size="0.025 0.15" material="leg_color" />
            <geom name="rear_right_lower_leg_collision" type="cylinder" group="3" rgba="0.5 0.5 0.5 0.3" pos="0 0 -0.15" size="0.025 0.15" />
          </body>
        </body>
      </body>
    </body>
  </worldbody>
  <actuator>
    <position name="front_left_hip_joint_motor" joint="front_left_hip_joint" kp="10" ctrlrange="-50.0 50.0" />
    <position name="front_left_shoulder_joint_motor" joint="front_left_shoulder_joint" kp="10" ctrlrange="-50.0 50.0" />
    <position name="front_left_knee_joint_motor" joint="front_left_knee_joint" kp="10" ctrlrange="-50.0 50.0" />
    <position name="front_right_hip_joint_motor" joint="front_right_hip_joint" kp="10" ctrlrange="-50.0 50.0" />
    <position name="front_right_shoulder_joint_motor" joint="front_right_shoulder_joint" kp="10" ctrlrange="-50.0 50.0" />
    <position name="front_right_knee_joint_motor" joint="front_right_knee_joint" kp="10" ctrlrange="-50.0 50.0" />
    <position name="rear_left_hip_joint_motor" joint="rear_left_hip_joint" kp="10" ctrlrange="-50.0 50.0" />
    <position name="rear_left_shoulder_joint_motor" joint="rear_left_shoulder_joint" kp="10" ctrlrange="-50.0 50.0" />
    <position name="rear_left_knee_joint_motor" joint="rear_left_knee_joint" kp="10" ctrlrange="-50.0 50.0" />
    <position name="rear_right_hip_joint_motor" joint="rear_right_hip_joint" kp="10" ctrlrange="-50.0 50.0" />
    <position name="rear_right_shoulder_joint_motor" joint="rear_right_shoulder_joint" kp="10" ctrlrange="-50.0 50.0" />
    <position name="rear_right_knee_joint_motor" joint="rear_right_knee_joint" kp="10" ctrlrange="-50.0 50.0" />
  </actuator>
  <sensor>
    <jointpos name="front_left_hip_joint_pos" joint="front_left_hip_joint" />
    <jointvel name="front_left_hip_joint_vel" joint="front_left_hip_joint" />
    <jointpos name="front_left_shoulder_joint_pos" joint="front_left_shoulder_joint" />
    <jointvel name="front_left_shoulder_joint_vel" joint="front_left_shoulder_joint" />
    <jointpos name="front_left_knee_joint_pos" joint="front_left_knee_joint" />
    <jointvel name="front_left_knee_joint_vel" joint="front_left_knee_joint" />
    <jointpos name="front_right_hip_joint_pos" joint="front_right_hip_joint" />
    <jointvel name="front_right_hip_joint_vel" joint="front_right_hip_joint" />
    <jointpos name="front_right_shoulder_joint_pos" joint="front_right_shoulder_joint" />
    <jointvel name="front_right_shoulder_joint_vel" joint="front_right_shoulder_joint" />
    <jointpos name="front_right_knee_joint_pos" joint="front_right_knee_joint" />
    <jointvel name="front_right_knee_joint_vel" joint="front_right_knee_joint" />
    <jointpos name="rear_left_hip_joint_pos" joint="rear_left_hip_joint" />
    <jointvel name="rear_left_hip_joint_vel" joint="rear_left_hip_joint" />
    <jointpos name="rear_left_shoulder_joint_pos" joint="rear_left_shoulder_joint" />
    <jointvel name="rear_left_shoulder_joint_vel" joint="rear_left_shoulder_joint" />
    <jointpos name="rear_left_knee_joint_pos" joint="rear_left_knee_joint" />
    <jointvel name="rear_left_knee_joint_vel" joint="rear_left_knee_joint" />
    <jointpos name="rear_right_hip_joint_pos" joint="rear_right_hip_joint" />
    <jointvel name="rear_right_hip_joint_vel" joint="rear_right_hip_joint" />
    <jointpos name="rear_right_shoulder_joint_pos" joint="rear_right_shoulder_joint" />
    <jointvel name="rear_right_shoulder_joint_vel" joint="rear_right_shoulder_joint" />
    <jointpos name="rear_right_knee_joint_pos" joint="rear_right_knee_joint" />
    <jointvel name="rear_right_knee_joint_vel" joint="rear_right_knee_joint" />
  </sensor>
</mujoco>