<?xml version="1.0"?>
<robot name="quadruped_robot">

  <!-- Main Body -->
  <link name="base_link">
    <visual>
      <origin xyz="0 0 0" rpy="0 0 0"/>
      <geometry>
        <box size="0.6 0.4 0.2"/>
      </geometry>
      <material name="body_color">
        <color rgba="0.8 0.8 0.8 1.0"/>
      </material>
    </visual>
    <collision>
      <origin xyz="0 0 0" rpy="0 0 0"/>
      <geometry>
        <box size="0.6 0.4 0.2"/>
      </geometry>
    </collision>
    <inertial>
      <origin xyz="0 0 0" rpy="0 0 0"/>
      <mass value="15.0"/>
      <inertia ixx="0.225" ixy="0.0" ixz="0.0"
               iyy="0.775" iyz="0.0"
               izz="0.925"/>
    </inertial>
  </link>

  <!-- FRONT LEFT LEG -->

  <!-- Front Left Hip -->
  <link name="front_left_hip">
    <visual>
      <origin xyz="0 0 -0.05" rpy="0 0 0"/>
      <geometry>
        <cylinder radius="0.04" length="0.1"/>
      </geometry>
      <material name="hip_color">
        <color rgba="0.3 0.3 0.3 1.0"/>
      </material>
    </visual>
    <collision>
      <origin xyz="0 0 -0.05" rpy="0 0 0"/>
      <geometry>
        <cylinder radius="0.04" length="0.1"/>
      </geometry>
    </collision>
    <inertial>
      <origin xyz="0 0 -0.05" rpy="0 0 0"/>
      <mass value="1.0"/>
      <inertia ixx="0.001" ixy="0.0" ixz="0.0"
               iyy="0.001" iyz="0.0"
               izz="0.001"/>
    </inertial>
  </link>

  <joint name="front_left_hip_joint" type="revolute">
    <parent link="base_link"/>
    <child link="front_left_hip"/>
    <origin xyz="0.25 0.15 -0.1" rpy="0 0 0"/>
    <axis xyz="0 0 1"/>
    <limit lower="-0.785" upper="0.785" effort="50.0" velocity="3.0"/>
    <dynamics damping="0.5" friction="0.1"/>
  </joint>

  <!-- Front Left Upper Leg -->
  <link name="front_left_upper_leg">
    <visual>
      <origin xyz="0 0 -0.15" rpy="0 0 0"/>
      <geometry>
        <cylinder radius="0.03" length="0.3"/>
      </geometry>
      <material name="leg_color">
        <color rgba="0.2 0.2 0.8 1.0"/>
      </material>
    </visual>
    <collision>
      <origin xyz="0 0 -0.15" rpy="0 0 0"/>
      <geometry>
        <cylinder radius="0.03" length="0.3"/>
      </geometry>
    </collision>
    <inertial>
      <origin xyz="0 0 -0.15" rpy="0 0 0"/>
      <mass value="0.8"/>
      <inertia ixx="0.006" ixy="0.0" ixz="0.0"
               iyy="0.006" iyz="0.0"
               izz="0.0007"/>
    </inertial>
  </link>

  <joint name="front_left_shoulder_joint" type="revolute">
    <parent link="front_left_hip"/>
    <child link="front_left_upper_leg"/>
    <origin xyz="0 0 -0.1" rpy="0 0 0"/>
    <axis xyz="1 0 0"/>
    <limit lower="-1.047" upper="1.047" effort="50.0" velocity="3.0"/>
    <dynamics damping="0.5" friction="0.1"/>
  </joint>

  <!-- Front Left Lower Leg -->
  <link name="front_left_lower_leg">
    <visual>
      <origin xyz="0 0 -0.15" rpy="0 0 0"/>
      <geometry>
        <cylinder radius="0.025" length="0.3"/>
      </geometry>
      <material name="leg_color">
        <color rgba="0.2 0.2 0.8 1.0"/>
      </material>
    </visual>
    <collision>
      <origin xyz="0 0 -0.15" rpy="0 0 0"/>
      <geometry>
        <cylinder radius="0.025" length="0.3"/>
      </geometry>
    </collision>
    <inertial>
      <origin xyz="0 0 -0.15" rpy="0 0 0"/>
      <mass value="0.7"/>
      <inertia ixx="0.005" ixy="0.0" ixz="0.0"
               iyy="0.005" iyz="0.0"
               izz="0.0006"/>
    </inertial>
  </link>

  <joint name="front_left_knee_joint" type="revolute">
    <parent link="front_left_upper_leg"/>
    <child link="front_left_lower_leg"/>
    <origin xyz="0 0 -0.3" rpy="0 0 0"/>
    <axis xyz="1 0 0"/>
    <limit lower="-2.094" upper="-0.174" effort="50.0" velocity="3.0"/>
    <dynamics damping="0.5" friction="0.1"/>
  </joint>

  <!-- FRONT RIGHT LEG -->

  <!-- Front Right Hip -->
  <link name="front_right_hip">
    <visual>
      <origin xyz="0 0 -0.05" rpy="0 0 0"/>
      <geometry>
        <cylinder radius="0.04" length="0.1"/>
      </geometry>
      <material name="hip_color">
        <color rgba="0.3 0.3 0.3 1.0"/>
      </material>
    </visual>
    <collision>
      <origin xyz="0 0 -0.05" rpy="0 0 0"/>
      <geometry>
        <cylinder radius="0.04" length="0.1"/>
      </geometry>
    </collision>
    <inertial>
      <origin xyz="0 0 -0.05" rpy="0 0 0"/>
      <mass value="1.0"/>
      <inertia ixx="0.001" ixy="0.0" ixz="0.0"
               iyy="0.001" iyz="0.0"
               izz="0.001"/>
    </inertial>
  </link>

  <joint name="front_right_hip_joint" type="revolute">
    <parent link="base_link"/>
    <child link="front_right_hip"/>
    <origin xyz="0.25 -0.15 -0.1" rpy="0 0 0"/>
    <axis xyz="0 0 1"/>
    <limit lower="-0.785" upper="0.785" effort="50.0" velocity="3.0"/>
    <dynamics damping="0.5" friction="0.1"/>
  </joint>

  <!-- Front Right Upper Leg -->
  <link name="front_right_upper_leg">
    <visual>
      <origin xyz="0 0 -0.15" rpy="0 0 0"/>
      <geometry>
        <cylinder radius="0.03" length="0.3"/>
      </geometry>
      <material name="leg_color"/>
    </visual>
    <collision>
      <origin xyz="0 0 -0.15" rpy="0 0 0"/>
      <geometry>
        <cylinder radius="0.03" length="0.3"/>
      </geometry>
    </collision>
    <inertial>
      <origin xyz="0 0 -0.15" rpy="0 0 0"/>
      <mass value="0.8"/>
      <inertia ixx="0.006" ixy="0.0" ixz="0.0"
               iyy="0.006" iyz="0.0"
               izz="0.0007"/>
    </inertial>
  </link>

  <joint name="front_right_shoulder_joint" type="revolute">
    <parent link="front_right_hip"/>
    <child link="front_right_upper_leg"/>
    <origin xyz="0 0 -0.1" rpy="0 0 0"/>
    <axis xyz="1 0 0"/>
    <limit lower="-1.047" upper="1.047" effort="50.0" velocity="3.0"/>
    <dynamics damping="0.5" friction="0.1"/>
  </joint>

  <!-- Front Right Lower Leg -->
  <link name="front_right_lower_leg">
    <visual>
      <origin xyz="0 0 -0.15" rpy="0 0 0"/>
      <geometry>
        <cylinder radius="0.025" length="0.3"/>
      </geometry>
      <material name="leg_color"/>
    </visual>
    <collision>
      <origin xyz="0 0 -0.15" rpy="0 0 0"/>
      <geometry>
        <cylinder radius="0.025" length="0.3"/>
      </geometry>
    </collision>
    <inertial>
      <origin xyz="0 0 -0.15" rpy="0 0 0"/>
      <mass value="0.7"/>
      <inertia ixx="0.005" ixy="0.0" ixz="0.0"
               iyy="0.005" iyz="0.0"
               izz="0.0006"/>
    </inertial>
  </link>

  <joint name="front_right_knee_joint" type="revolute">
    <parent link="front_right_upper_leg"/>
    <child link="front_right_lower_leg"/>
    <origin xyz="0 0 -0.3" rpy="0 0 0"/>
    <axis xyz="1 0 0"/>
    <limit lower="-2.094" upper="-0.174" effort="50.0" velocity="3.0"/>
    <dynamics damping="0.5" friction="0.1"/>
  </joint>

  <!-- REAR LEFT LEG -->

  <!-- Rear Left Hip -->
  <link name="rear_left_hip">
    <visual>
      <origin xyz="0 0 -0.05" rpy="0 0 0"/>
      <geometry>
        <cylinder radius="0.04" length="0.1"/>
      </geometry>
      <material name="hip_color"/>
    </visual>
    <collision>
      <origin xyz="0 0 -0.05" rpy="0 0 0"/>
      <geometry>
        <cylinder radius="0.04" length="0.1"/>
      </geometry>
    </collision>
    <inertial>
      <origin xyz="0 0 -0.05" rpy="0 0 0"/>
      <mass value="1.0"/>
      <inertia ixx="0.001" ixy="0.0" ixz="0.0"
               iyy="0.001" iyz="0.0"
               izz="0.001"/>
    </inertial>
  </link>

  <joint name="rear_left_hip_joint" type="revolute">
    <parent link="base_link"/>
    <child link="rear_left_hip"/>
    <origin xyz="-0.25 0.15 -0.1" rpy="0 0 0"/>
    <axis xyz="0 0 1"/>
    <limit lower="-0.785" upper="0.785" effort="50.0" velocity="3.0"/>
    <dynamics damping="0.5" friction="0.1"/>
  </joint>

  <!-- Rear Left Upper Leg -->
  <link name="rear_left_upper_leg">
    <visual>
      <origin xyz="0 0 -0.15" rpy="0 0 0"/>
      <geometry>
        <cylinder radius="0.03" length="0.3"/>
      </geometry>
      <material name="leg_color"/>
    </visual>
    <collision>
      <origin xyz="0 0 -0.15" rpy="0 0 0"/>
      <geometry>
        <cylinder radius="0.03" length="0.3"/>
      </geometry>
    </collision>
    <inertial>
      <origin xyz="0 0 -0.15" rpy="0 0 0"/>
      <mass value="0.8"/>
      <inertia ixx="0.006" ixy="0.0" ixz="0.0"
               iyy="0.006" iyz="0.0"
               izz="0.0007"/>
    </inertial>
  </link>

  <joint name="rear_left_shoulder_joint" type="revolute">
    <parent link="rear_left_hip"/>
    <child link="rear_left_upper_leg"/>
    <origin xyz="0 0 -0.1" rpy="0 0 0"/>
    <axis xyz="1 0 0"/>
    <limit lower="-1.047" upper="1.047" effort="50.0" velocity="3.0"/>
    <dynamics damping="0.5" friction="0.1"/>
  </joint>

  <!-- Rear Left Lower Leg -->
  <link name="rear_left_lower_leg">
    <visual>
      <origin xyz="0 0 -0.15" rpy="0 0 0"/>
      <geometry>
        <cylinder radius="0.025" length="0.3"/>
      </geometry>
      <material name="leg_color"/>
    </visual>
    <collision>
      <origin xyz="0 0 -0.15" rpy="0 0 0"/>
      <geometry>
        <cylinder radius="0.025" length="0.3"/>
      </geometry>
    </collision>
    <inertial>
      <origin xyz="0 0 -0.15" rpy="0 0 0"/>
      <mass value="0.7"/>
      <inertia ixx="0.005" ixy="0.0" ixz="0.0"
               iyy="0.005" iyz="0.0"
               izz="0.0006"/>
    </inertial>
  </link>

  <joint name="rear_left_knee_joint" type="revolute">
    <parent link="rear_left_upper_leg"/>
    <child link="rear_left_lower_leg"/>
    <origin xyz="0 0 -0.3" rpy="0 0 0"/>
    <axis xyz="1 0 0"/>
    <limit lower="-2.094" upper="-0.174" effort="50.0" velocity="3.0"/>
    <dynamics damping="0.5" friction="0.1"/>
  </joint>

  <!-- REAR RIGHT LEG -->

  <!-- Rear Right Hip -->
  <link name="rear_right_hip">
    <visual>
      <origin xyz="0 0 -0.05" rpy="0 0 0"/>
      <geometry>
        <cylinder radius="0.04" length="0.1"/>
      </geometry>
      <material name="hip_color"/>
    </visual>
    <collision>
      <origin xyz="0 0 -0.05" rpy="0 0 0"/>
      <geometry>
        <cylinder radius="0.04" length="0.1"/>
      </geometry>
    </collision>
    <inertial>
      <origin xyz="0 0 -0.05" rpy="0 0 0"/>
      <mass value="1.0"/>
      <inertia ixx="0.001" ixy="0.0" ixz="0.0"
               iyy="0.001" iyz="0.0"
               izz="0.001"/>
    </inertial>
  </link>

  <joint name="rear_right_hip_joint" type="revolute">
    <parent link="base_link"/>
    <child link="rear_right_hip"/>
    <origin xyz="-0.25 -0.15 -0.1" rpy="0 0 0"/>
    <axis xyz="0 0 1"/>
    <limit lower="-0.785" upper="0.785" effort="50.0" velocity="3.0"/>
    <dynamics damping="0.5" friction="0.1"/>
  </joint>

  <!-- Rear Right Upper Leg -->
  <link name="rear_right_upper_leg">
    <visual>
      <origin xyz="0 0 -0.15" rpy="0 0 0"/>
      <geometry>
        <cylinder radius="0.03" length="0.3"/>
      </geometry>
      <material name="leg_color"/>
    </visual>
    <collision>
      <origin xyz="0 0 -0.15" rpy="0 0 0"/>
      <geometry>
        <cylinder radius="0.03" length="0.3"/>
      </geometry>
    </collision>
    <inertial>
      <origin xyz="0 0 -0.15" rpy="0 0 0"/>
      <mass value="0.8"/>
      <inertia ixx="0.006" ixy="0.0" ixz="0.0"
               iyy="0.006" iyz="0.0"
               izz="0.0007"/>
    </inertial>
  </link>

  <joint name="rear_right_shoulder_joint" type="revolute">
    <parent link="rear_right_hip"/>
    <child link="rear_right_upper_leg"/>
    <origin xyz="0 0 -0.1" rpy="0 0 0"/>
    <axis xyz="1 0 0"/>
    <limit lower="-1.047" upper="1.047" effort="50.0" velocity="3.0"/>
    <dynamics damping="0.5" friction="0.1"/>
  </joint>

  <!-- Rear Right Lower Leg -->
  <link name="rear_right_lower_leg">
    <visual>
      <origin xyz="0 0 -0.15" rpy="0 0 0"/>
      <geometry>
        <cylinder radius="0.025" length="0.3"/>
      </geometry>
      <material name="leg_color"/>
    </visual>
    <collision>
      <origin xyz="0 0 -0.15" rpy="0 0 0"/>
      <geometry>
        <cylinder radius="0.025" length="0.3"/>
      </geometry>
    </collision>
    <inertial>
      <origin xyz="0 0 -0.15" rpy="0 0 0"/>
      <mass value="0.7"/>
      <inertia ixx="0.005" ixy="0.0" ixz="0.0"
               iyy="0.005" iyz="0.0"
               izz="0.0006"/>
    </inertial>
  </link>

  <joint name="rear_right_knee_joint" type="revolute">
    <parent link="rear_right_upper_leg"/>
    <child link="rear_right_lower_leg"/>
    <origin xyz="0 0 -0.3" rpy="0 0 0"/>
    <axis xyz="1 0 0"/>
    <limit lower="-2.094" upper="-0.174" effort="50.0" velocity="3.0"/>
    <dynamics damping="0.5" friction="0.1"/>
  </joint>

</robot>
