<?xml version="1.0"?>
<robot name="humanoid_robot">

  <!-- Base Link (Pelvis - Center of Mass) -->
  <link name="base_link">
    <visual>
      <origin xyz="0 0 0" rpy="0 0 0"/>
      <geometry>
        <box size="0.3 0.2 0.15"/>
      </geometry>
      <material name="pelvis_color">
        <color rgba="0.7 0.7 0.7 1.0"/>
      </material>
    </visual>
    <collision>
      <origin xyz="0 0 0" rpy="0 0 0"/>
      <geometry>
        <box size="0.3 0.2 0.15"/>
      </geometry>
    </collision>
    <inertial>
      <origin xyz="0 0 0" rpy="0 0 0"/>
      <mass value="5.0"/>
      <inertia ixx="0.018" ixy="0.0" ixz="0.0"
               iyy="0.023" iyz="0.0"
               izz="0.027"/>
    </inertial>
  </link>

  <!-- Torso -->
  <link name="torso">
    <visual>
      <origin xyz="0 0 0.25" rpy="0 0 0"/>
      <geometry>
        <box size="0.35 0.25 0.5"/>
      </geometry>
      <material name="body_color">
        <color rgba="0.8 0.8 0.8 1.0"/>
      </material>
    </visual>
    <collision>
      <origin xyz="0 0 0.25" rpy="0 0 0"/>
      <geometry>
        <box size="0.35 0.25 0.5"/>
      </geometry>
    </collision>
    <inertial>
      <origin xyz="0 0 0.25" rpy="0 0 0"/>
      <mass value="20.0"/>
      <inertia ixx="0.533" ixy="0.0" ixz="0.0"
               iyy="0.616" iyz="0.0"
               izz="0.208"/>
    </inertial>
  </link>

  <joint name="pelvis_to_torso" type="fixed">
    <parent link="base_link"/>
    <child link="torso"/>
    <origin xyz="0 0 0.075" rpy="0 0 0"/>
  </joint>

  <!-- Head -->
  <link name="head">
    <visual>
      <origin xyz="0 0 0" rpy="0 0 0"/>
      <geometry>
        <sphere radius="0.15"/>
      </geometry>
      <material name="head_color">
        <color rgba="0.9 0.8 0.7 1.0"/>
      </material>
    </visual>
    <collision>
      <origin xyz="0 0 0" rpy="0 0 0"/>
      <geometry>
        <sphere radius="0.15"/>
      </geometry>
    </collision>
    <inertial>
      <origin xyz="0 0 0" rpy="0 0 0"/>
      <mass value="4.0"/>
      <inertia ixx="0.036" ixy="0.0" ixz="0.0"
               iyy="0.036" iyz="0.0"
               izz="0.036"/>
    </inertial>
  </link>

  <joint name="neck_pitch" type="revolute">
    <parent link="torso"/>
    <child link="head"/>
    <origin xyz="0 0 0.6" rpy="0 0 0"/>
    <axis xyz="0 1 0"/>
    <limit lower="-0.785" upper="0.785" effort="20.0" velocity="2.0"/>
    <dynamics damping="0.5" friction="0.1"/>
  </joint>

  <!-- IMU Sensor -->
  <link name="imu_link">
    <visual>
      <origin xyz="0 0 0" rpy="0 0 0"/>
      <geometry>
        <box size="0.02 0.02 0.01"/>
      </geometry>
      <material name="sensor_color">
        <color rgba="0.8 0.2 0.2 1.0"/>
      </material>
    </visual>
    <inertial>
      <origin xyz="0 0 0" rpy="0 0 0"/>
      <mass value="0.01"/>
      <inertia ixx="0.00001" ixy="0.0" ixz="0.0"
               iyy="0.00001" iyz="0.0"
               izz="0.00001"/>
    </inertial>
  </link>

  <joint name="imu_joint" type="fixed">
    <parent link="torso"/>
    <child link="imu_link"/>
    <origin xyz="0 0 0.25" rpy="0 0 0"/>
  </joint>

  <!-- LEFT ARM -->

  <!-- Left Shoulder -->
  <link name="left_shoulder">
    <visual>
      <origin xyz="0 0 0" rpy="0 0 0"/>
      <geometry>
        <sphere radius="0.05"/>
      </geometry>
      <material name="joint_color">
        <color rgba="0.3 0.3 0.3 1.0"/>
      </material>
    </visual>
    <inertial>
      <origin xyz="0 0 0" rpy="0 0 0"/>
      <mass value="0.5"/>
      <inertia ixx="0.001" ixy="0.0" ixz="0.0"
               iyy="0.001" iyz="0.0"
               izz="0.001"/>
    </inertial>
  </link>

  <joint name="left_shoulder_pitch" type="revolute">
    <parent link="torso"/>
    <child link="left_shoulder"/>
    <origin xyz="0 0.2 0.45" rpy="0 0 0"/>
    <axis xyz="0 1 0"/>
    <limit lower="-3.14" upper="3.14" effort="30.0" velocity="3.0"/>
    <dynamics damping="0.5" friction="0.1"/>
  </joint>

  <!-- Left Upper Arm -->
  <link name="left_upper_arm">
    <visual>
      <origin xyz="0 0.15 0" rpy="0 0 0"/>
      <geometry>
        <cylinder radius="0.05" length="0.3"/>
      </geometry>
      <material name="arm_color">
        <color rgba="0.7 0.7 0.7 1.0"/>
      </material>
    </visual>
    <collision>
      <origin xyz="0 0.15 0" rpy="0 0 0"/>
      <geometry>
        <cylinder radius="0.05" length="0.3"/>
      </geometry>
    </collision>
    <inertial>
      <origin xyz="0 0.15 0" rpy="0 0 0"/>
      <mass value="2.0"/>
      <inertia ixx="0.016" ixy="0.0" ixz="0.0"
               iyy="0.001" iyz="0.0"
               izz="0.016"/>
    </inertial>
  </link>

  <joint name="left_shoulder_roll" type="revolute">
    <parent link="left_shoulder"/>
    <child link="left_upper_arm"/>
    <origin xyz="0 0 0" rpy="0 0 0"/>
    <axis xyz="1 0 0"/>
    <limit lower="-1.57" upper="1.57" effort="30.0" velocity="3.0"/>
    <dynamics damping="0.5" friction="0.1"/>
  </joint>

  <!-- Left Lower Arm -->
  <link name="left_lower_arm">
    <visual>
      <origin xyz="0 0.125 0" rpy="0 0 0"/>
      <geometry>
        <cylinder radius="0.04" length="0.25"/>
      </geometry>
      <material name="arm_color"/>
    </visual>
    <collision>
      <origin xyz="0 0.125 0" rpy="0 0 0"/>
      <geometry>
        <cylinder radius="0.04" length="0.25"/>
      </geometry>
    </collision>
    <inertial>
      <origin xyz="0 0.125 0" rpy="0 0 0"/>
      <mass value="1.5"/>
      <inertia ixx="0.008" ixy="0.0" ixz="0.0"
               iyy="0.001" iyz="0.0"
               izz="0.008"/>
    </inertial>
  </link>

  <joint name="left_elbow" type="revolute">
    <parent link="left_upper_arm"/>
    <child link="left_lower_arm"/>
    <origin xyz="0 0.3 0" rpy="0 0 0"/>
    <axis xyz="0 1 0"/>
    <limit lower="0" upper="2.618" effort="20.0" velocity="3.0"/>
    <dynamics damping="0.5" friction="0.1"/>
  </joint>

  <!-- Left Hand -->
  <link name="left_hand">
    <visual>
      <origin xyz="0 0.05 0" rpy="0 0 0"/>
      <geometry>
        <box size="0.08 0.1 0.02"/>
      </geometry>
      <material name="hand_color">
        <color rgba="0.9 0.8 0.7 1.0"/>
      </material>
    </visual>
    <collision>
      <origin xyz="0 0.05 0" rpy="0 0 0"/>
      <geometry>
        <box size="0.08 0.1 0.02"/>
      </geometry>
    </collision>
    <inertial>
      <origin xyz="0 0.05 0" rpy="0 0 0"/>
      <mass value="0.3"/>
      <inertia ixx="0.0003" ixy="0.0" ixz="0.0"
               iyy="0.0002" iyz="0.0"
               izz="0.0002"/>
    </inertial>
  </link>

  <joint name="left_wrist" type="fixed">
    <parent link="left_lower_arm"/>
    <child link="left_hand"/>
    <origin xyz="0 0.25 0" rpy="0 0 0"/>
  </joint>

  <!-- RIGHT ARM (mirror of left) -->

  <link name="right_shoulder">
    <visual>
      <origin xyz="0 0 0" rpy="0 0 0"/>
      <geometry>
        <sphere radius="0.05"/>
      </geometry>
      <material name="joint_color"/>
    </visual>
    <inertial>
      <origin xyz="0 0 0" rpy="0 0 0"/>
      <mass value="0.5"/>
      <inertia ixx="0.001" ixy="0.0" ixz="0.0"
               iyy="0.001" iyz="0.0"
               izz="0.001"/>
    </inertial>
  </link>

  <joint name="right_shoulder_pitch" type="revolute">
    <parent link="torso"/>
    <child link="right_shoulder"/>
    <origin xyz="0 -0.2 0.45" rpy="0 0 0"/>
    <axis xyz="0 1 0"/>
    <limit lower="-3.14" upper="3.14" effort="30.0" velocity="3.0"/>
    <dynamics damping="0.5" friction="0.1"/>
  </joint>

  <link name="right_upper_arm">
    <visual>
      <origin xyz="0 -0.15 0" rpy="0 0 0"/>
      <geometry>
        <cylinder radius="0.05" length="0.3"/>
      </geometry>
      <material name="arm_color"/>
    </visual>
    <collision>
      <origin xyz="0 -0.15 0" rpy="0 0 0"/>
      <geometry>
        <cylinder radius="0.05" length="0.3"/>
      </geometry>
    </collision>
    <inertial>
      <origin xyz="0 -0.15 0" rpy="0 0 0"/>
      <mass value="2.0"/>
      <inertia ixx="0.016" ixy="0.0" ixz="0.0"
               iyy="0.001" iyz="0.0"
               izz="0.016"/>
    </inertial>
  </link>

  <joint name="right_shoulder_roll" type="revolute">
    <parent link="right_shoulder"/>
    <child link="right_upper_arm"/>
    <origin xyz="0 0 0" rpy="0 0 0"/>
    <axis xyz="1 0 0"/>
    <limit lower="-1.57" upper="1.57" effort="30.0" velocity="3.0"/>
    <dynamics damping="0.5" friction="0.1"/>
  </joint>

  <link name="right_lower_arm">
    <visual>
      <origin xyz="0 -0.125 0" rpy="0 0 0"/>
      <geometry>
        <cylinder radius="0.04" length="0.25"/>
      </geometry>
      <material name="arm_color"/>
    </visual>
    <collision>
      <origin xyz="0 -0.125 0" rpy="0 0 0"/>
      <geometry>
        <cylinder radius="0.04" length="0.25"/>
      </geometry>
    </collision>
    <inertial>
      <origin xyz="0 -0.125 0" rpy="0 0 0"/>
      <mass value="1.5"/>
      <inertia ixx="0.008" ixy="0.0" ixz="0.0"
               iyy="0.001" iyz="0.0"
               izz="0.008"/>
    </inertial>
  </link>

  <joint name="right_elbow" type="revolute">
    <parent link="right_upper_arm"/>
    <child link="right_lower_arm"/>
    <origin xyz="0 -0.3 0" rpy="0 0 0"/>
    <axis xyz="0 1 0"/>
    <limit lower="0" upper="2.618" effort="20.0" velocity="3.0"/>
    <dynamics damping="0.5" friction="0.1"/>
  </joint>

  <link name="right_hand">
    <visual>
      <origin xyz="0 -0.05 0" rpy="0 0 0"/>
      <geometry>
        <box size="0.08 0.1 0.02"/>
      </geometry>
      <material name="hand_color"/>
    </visual>
    <collision>
      <origin xyz="0 -0.05 0" rpy="0 0 0"/>
      <geometry>
        <box size="0.08 0.1 0.02"/>
      </geometry>
    </collision>
    <inertial>
      <origin xyz="0 -0.05 0" rpy="0 0 0"/>
      <mass value="0.3"/>
      <inertia ixx="0.0003" ixy="0.0" ixz="0.0"
               iyy="0.0002" iyz="0.0"
               izz="0.0002"/>
    </inertial>
  </link>

  <joint name="right_wrist" type="fixed">
    <parent link="right_lower_arm"/>
    <child link="right_hand"/>
    <origin xyz="0 -0.25 0" rpy="0 0 0"/>
  </joint>

  <!-- LEFT LEG -->

  <link name="left_hip">
    <visual>
      <origin xyz="0 0 0" rpy="0 0 0"/>
      <geometry>
        <sphere radius="0.06"/>
      </geometry>
      <material name="joint_color"/>
    </visual>
    <inertial>
      <origin xyz="0 0 0" rpy="0 0 0"/>
      <mass value="1.0"/>
      <inertia ixx="0.001" ixy="0.0" ixz="0.0"
               iyy="0.001" iyz="0.0"
               izz="0.001"/>
    </inertial>
  </link>

  <joint name="left_hip_pitch" type="revolute">
    <parent link="base_link"/>
    <child link="left_hip"/>
    <origin xyz="0 0.1 -0.075" rpy="0 0 0"/>
    <axis xyz="0 1 0"/>
    <limit lower="-2.094" upper="2.094" effort="100.0" velocity="3.0"/>
    <dynamics damping="1.0" friction="0.5"/>
  </joint>

  <link name="left_upper_leg">
    <visual>
      <origin xyz="0 0 -0.2" rpy="0 0 0"/>
      <geometry>
        <cylinder radius="0.06" length="0.4"/>
      </geometry>
      <material name="leg_color">
        <color rgba="0.2 0.2 0.8 1.0"/>
      </material>
    </visual>
    <collision>
      <origin xyz="0 0 -0.2" rpy="0 0 0"/>
      <geometry>
        <cylinder radius="0.06" length="0.4"/>
      </geometry>
    </collision>
    <inertial>
      <origin xyz="0 0 -0.2" rpy="0 0 0"/>
      <mass value="4.0"/>
      <inertia ixx="0.054" ixy="0.0" ixz="0.0"
               iyy="0.054" iyz="0.0"
               izz="0.007"/>
    </inertial>
  </link>

  <joint name="left_hip_roll" type="revolute">
    <parent link="left_hip"/>
    <child link="left_upper_leg"/>
    <origin xyz="0 0 0" rpy="0 0 0"/>
    <axis xyz="1 0 0"/>
    <limit lower="-0.785" upper="0.785" effort="100.0" velocity="3.0"/>
    <dynamics damping="1.0" friction="0.5"/>
  </joint>

  <link name="left_lower_leg">
    <visual>
      <origin xyz="0 0 -0.2" rpy="0 0 0"/>
      <geometry>
        <cylinder radius="0.05" length="0.4"/>
      </geometry>
      <material name="leg_color"/>
    </visual>
    <collision>
      <origin xyz="0 0 -0.2" rpy="0 0 0"/>
      <geometry>
        <cylinder radius="0.05" length="0.4"/>
      </geometry>
    </collision>
    <inertial>
      <origin xyz="0 0 -0.2" rpy="0 0 0"/>
      <mass value="3.0"/>
      <inertia ixx="0.041" ixy="0.0" ixz="0.0"
               iyy="0.041" iyz="0.0"
               izz="0.004"/>
    </inertial>
  </link>

  <joint name="left_knee" type="revolute">
    <parent link="left_upper_leg"/>
    <child link="left_lower_leg"/>
    <origin xyz="0 0 -0.4" rpy="0 0 0"/>
    <axis xyz="0 1 0"/>
    <limit lower="0" upper="2.618" effort="100.0" velocity="3.0"/>
    <dynamics damping="1.0" friction="0.5"/>
  </joint>

  <link name="left_foot">
    <visual>
      <origin xyz="0.08 0 -0.04" rpy="0 0 0"/>
      <geometry>
        <box size="0.25 0.12 0.08"/>
      </geometry>
      <material name="foot_color">
        <color rgba="0.3 0.3 0.3 1.0"/>
      </material>
    </visual>
    <collision>
      <origin xyz="0.08 0 -0.04" rpy="0 0 0"/>
      <geometry>
        <box size="0.25 0.12 0.08"/>
      </geometry>
    </collision>
    <inertial>
      <origin xyz="0.08 0 -0.04" rpy="0 0 0"/>
      <mass value="1.0"/>
      <inertia ixx="0.002" ixy="0.0" ixz="0.0"
               iyy="0.006" iyz="0.0"
               izz="0.007"/>
    </inertial>
  </link>

  <joint name="left_ankle" type="fixed">
    <parent link="left_lower_leg"/>
    <child link="left_foot"/>
    <origin xyz="0 0 -0.4" rpy="0 0 0"/>
  </joint>

  <!-- RIGHT LEG (mirror of left) -->

  <link name="right_hip">
    <visual>
      <origin xyz="0 0 0" rpy="0 0 0"/>
      <geometry>
        <sphere radius="0.06"/>
      </geometry>
      <material name="joint_color"/>
    </visual>
    <inertial>
      <origin xyz="0 0 0" rpy="0 0 0"/>
      <mass value="1.0"/>
      <inertia ixx="0.001" ixy="0.0" ixz="0.0"
               iyy="0.001" iyz="0.0"
               izz="0.001"/>
    </inertial>
  </link>

  <joint name="right_hip_pitch" type="revolute">
    <parent link="base_link"/>
    <child link="right_hip"/>
    <origin xyz="0 -0.1 -0.075" rpy="0 0 0"/>
    <axis xyz="0 1 0"/>
    <limit lower="-2.094" upper="2.094" effort="100.0" velocity="3.0"/>
    <dynamics damping="1.0" friction="0.5"/>
  </joint>

  <link name="right_upper_leg">
    <visual>
      <origin xyz="0 0 -0.2" rpy="0 0 0"/>
      <geometry>
        <cylinder radius="0.06" length="0.4"/>
      </geometry>
      <material name="leg_color"/>
    </visual>
    <collision>
      <origin xyz="0 0 -0.2" rpy="0 0 0"/>
      <geometry>
        <cylinder radius="0.06" length="0.4"/>
      </geometry>
    </collision>
    <inertial>
      <origin xyz="0 0 -0.2" rpy="0 0 0"/>
      <mass value="4.0"/>
      <inertia ixx="0.054" ixy="0.0" ixz="0.0"
               iyy="0.054" iyz="0.0"
               izz="0.007"/>
    </inertial>
  </link>

  <joint name="right_hip_roll" type="revolute">
    <parent link="right_hip"/>
    <child link="right_upper_leg"/>
    <origin xyz="0 0 0" rpy="0 0 0"/>
    <axis xyz="1 0 0"/>
    <limit lower="-0.785" upper="0.785" effort="100.0" velocity="3.0"/>
    <dynamics damping="1.0" friction="0.5"/>
  </joint>

  <link name="right_lower_leg">
    <visual>
      <origin xyz="0 0 -0.2" rpy="0 0 0"/>
      <geometry>
        <cylinder radius="0.05" length="0.4"/>
      </geometry>
      <material name="leg_color"/>
    </visual>
    <collision>
      <origin xyz="0 0 -0.2" rpy="0 0 0"/>
      <geometry>
        <cylinder radius="0.05" length="0.4"/>
      </geometry>
    </collision>
    <inertial>
      <origin xyz="0 0 -0.2" rpy="0 0 0"/>
      <mass value="3.0"/>
      <inertia ixx="0.041" ixy="0.0" ixz="0.0"
               iyy="0.041" iyz="0.0"
               izz="0.004"/>
    </inertial>
  </link>

  <joint name="right_knee" type="revolute">
    <parent link="right_upper_leg"/>
    <child link="right_lower_leg"/>
    <origin xyz="0 0 -0.4" rpy="0 0 0"/>
    <axis xyz="0 1 0"/>
    <limit lower="0" upper="2.618" effort="100.0" velocity="3.0"/>
    <dynamics damping="1.0" friction="0.5"/>
  </joint>

  <link name="right_foot">
    <visual>
      <origin xyz="0.08 0 -0.04" rpy="0 0 0"/>
      <geometry>
        <box size="0.25 0.12 0.08"/>
      </geometry>
      <material name="foot_color"/>
    </visual>
    <collision>
      <origin xyz="0.08 0 -0.04" rpy="0 0 0"/>
      <geometry>
        <box size="0.25 0.12 0.08"/>
      </geometry>
    </collision>
    <inertial>
      <origin xyz="0.08 0 -0.04" rpy="0 0 0"/>
      <mass value="1.0"/>
      <inertia ixx="0.002" ixy="0.0" ixz="0.0"
               iyy="0.006" iyz="0.0"
               izz="0.007"/>
    </inertial>
  </link>

  <joint name="right_ankle" type="fixed">
    <parent link="right_lower_leg"/>
    <child link="right_foot"/>
    <origin xyz="0 0 -0.4" rpy="0 0 0"/>
  </joint>

</robot>
