<?xml version='1.0' encoding='utf-8'?>
<mujoco model="simple_differential_drive">
  <compiler angle="radian" meshdir="roboshire/examples/differential_drive/meshes" autolimits="true" />
  <option timestep="0.001" gravity="0 0 -9.81" />
  <default>
    <geom rgba="0.8 0.6 0.4 1" friction="1 0.5 0.5" />
  </default>
  <asset>
    <material name="blue" rgba="0.2 0.3 0.8 1.0" />
    <material name="black" rgba="0.1 0.1 0.1 1.0" />
    <material name="grey" rgba="0.5 0.5 0.5 1.0" />
    <material name="red" rgba="0.8 0.2 0.2 1.0" />
  </asset>
  <worldbody>
    <light diffuse="0.5 0.5 0.5" pos="0 0 3" dir="0 0 -1" />
    <geom name="floor" type="plane" size="0 0 1" rgba="0.9 0.9 0.9 1" />
    <body name="base_link" pos="0 0 0.5">
      <freejoint name="base_link_freejoint" />
      <inertial mass="5.0" pos="0 0 0" fullinertia="0.1 0.1 0.1 0.0 0.0 0.0" />
      <geom name="base_link_visual" type="box" group="0" size="0.2 0.15 0.075" material="blue" />
      <geom name="base_link_collision" type="box" group="3" rgba="0.5 0.5 0.5 0.3" size="0.2 0.15 0.075" />
      <body name="left_wheel" pos="0.1 0.175 0">
        <joint name="left_wheel_joint" type="hinge" axis="0 1 0" />
        <inertial mass="0.5" pos="0 0 0" fullinertia="0.01 0.01 0.01 0.0 0.0 0.0" />
        <geom name="left_wheel_visual" type="cylinder" group="0" pos="0 0 0" quat="0.7071054825112363 0.7071080798594735 0.0 0.0" size="0.1 0.025" material="black" />
        <geom name="left_wheel_collision" type="cylinder" group="3" rgba="0.5 0.5 0.5 0.3" pos="0 0 0" quat="0.7071054825112363 0.7071080798594735 0.0 0.0" size="0.1 0.025" />
      </body>
      <body name="right_wheel" pos="0.1 -0.175 0">
        <joint name="right_wheel_joint" type="hinge" axis="0 1 0" />
        <inertial mass="0.5" pos="0 0 0" fullinertia="0.01 0.01 0.01 0.0 0.0 0.0" />
        <geom name="right_wheel_visual" type="cylinder" group="0" pos="0 0 0" quat="0.7071054825112363 0.7071080798594735 0.0 0.0" size="0.1 0.025" material="black" />
        <geom name="right_wheel_collision" type="cylinder" group="3" rgba="0.5 0.5 0.5 0.3" pos="0 0 0" quat="0.7071054825112363 0.7071080798594735 0.0 0.0" size="0.1 0.025" />
      </body>
      <body name="caster_wheel" pos="-0.15 0 -0.05">
        <inertial mass="0.1" pos="0 0 0" fullinertia="0.001 0.001 0.001 0.0 0.0 0.0" />
        <geom name="caster_wheel_visual" type="sphere" group="0" size="0.05" material="grey" />
        <geom name="caster_wheel_collision" type="sphere" group="3" rgba="0.5 0.5 0.5 0.3" size="0.05" />
      </body>
      <body name="imu_link" pos="0 0 0.08">
        <inertial mass="0.01" pos="0 0 0" fullinertia="0.0001 0.0001 0.0001 0.0 0.0 0.0" />
        <geom name="imu_link_visual" type="box" group="0" size="0.01 0.01 0.005" material="red" />
      </body>
    </body>
  </worldbody>
  <actuator>
    <position name="left_wheel_joint_motor" joint="left_wheel_joint" kp="10" />
    <position name="right_wheel_joint_motor" joint="right_wheel_joint" kp="10" />
  </actuator>
  <sensor>
    <jointpos name="left_wheel_joint_pos" joint="left_wheel_joint" />
    <jointvel name="left_wheel_joint_vel" joint="left_wheel_joint" />
    <jointpos name="right_wheel_joint_pos" joint="right_wheel_joint" />
    <jointvel name="right_wheel_joint_vel" joint="right_wheel_joint" />
  </sensor>
</mujoco>